<?xml version="1.0" encoding="utf-8"?>
<!-- This URDF was automatically created by SolidWorks to URDF Exporter! Originally created by Stephen Brawner (brawner@gmail.com) 
     Commit Version: 1.6.0-4-g7f85cfe  Build Version: 1.6.7995.38578
     For more information, please see http://wiki.ros.org/sw_urdf_exporter -->
<robot
  name="Arm">

  <!-- ================================================================ -->
  <!-- Fixed-base mount for Gazebo                                     -->
  <!-- Gazebo treats the specially named "world" link as the inertial   -->
  <!-- world. This fixed joint rigidly mounts the arm base to the world -->
  <!-- while leaving all seven actuated joints controllable.            -->
  <!-- It also makes world the URDF root, avoiding the KDL warning about -->
  <!-- an inertial block on the root base_link.                          -->
  <!-- ================================================================ -->
  <link name="world" />

  <joint name="world_to_base_fixed_joint" type="fixed">
    <origin xyz="0 0 0" rpy="0 0 0" />
    <parent link="world" />
    <child link="base_link" />
  </joint>

  <link
    name="base_link">
    <inertial>
      <origin
        xyz="0.00110280922060463 -1.98703837603586E-05 0.0390910140862879"
        rpy="0 0 0" />
      <mass
        value="0.766851050223606" />
      <inertia
        ixx="0.00181952459266476"
        ixy="4.6709925751517E-07"
        ixz="2.90512573822122E-05"
        iyy="0.00175770181428764"
        iyz="-1.79295513788847E-07"
        izz="0.00301277451685566" />
    </inertial>
    <visual>
      <origin
        xyz="0 0 0"
        rpy="0 0 0" />
      <geometry>
        <mesh
          filename="package://arm_sim_node/urdf/meshes/base_link.STL" />
      </geometry>
      <material
        name="">
        <color
          rgba="0.898039215686275 0.917647058823529 0.929411764705882 1" />
      </material>
    </visual>
    <collision>
      <origin
        xyz="0 0 0"
        rpy="0 0 0" />
      <geometry>
        <mesh
          filename="package://arm_sim_node/urdf/meshes/base_link.STL" />
      </geometry>
    </collision>
  </link>
  <link
    name="link1">
    <inertial>
      <origin
        xyz="3.99351013802084E-05 2.96986005835023E-07 0.0979878098842334"
        rpy="0 0 0" />
      <mass
        value="2.22318567608356" />
      <inertia
        ixx="0.0105769901062"
        ixy="-1.03095907575644E-06"
        ixz="9.30832684723888E-05"
        iyy="0.0112071774977816"
        iyz="-1.49157928808864E-08"
        izz="0.00659269034666982" />
    </inertial>
    <visual>
      <origin
        xyz="0 0 0"
        rpy="0 0 0" />
      <geometry>
        <mesh
          filename="package://arm_sim_node/urdf/meshes/link1.STL" />
      </geometry>
      <material
        name="">
        <color
          rgba="0.898039215686275 0.917647058823529 0.929411764705882 1" />
      </material>
    </visual>
    <collision>
      <origin
        xyz="0 0 0"
        rpy="0 0 0" />
      <geometry>
        <mesh
          filename="package://arm_sim_node/urdf/meshes/link1.STL" />
      </geometry>
    </collision>
  </link>
  <joint
    name="joint1"
    type="revolute">
    <origin
      xyz="0 0 0.067"
      rpy="0 0 1.5707963267949" />
    <parent
      link="base_link" />
    <child
      link="link1" />
    <axis
      xyz="0 0 1" />
    <limit
      lower="-3.14"
      upper="3.14"
      effort="100"
      velocity="100" />
  </joint>
  <link
    name="link2">
    <inertial>
      <origin
        xyz="7.02671045918066E-11 0.0426351402886548 -0.0482569721337471"
        rpy="0 0 0" />
      <mass
        value="1.25469347638256" />
      <inertia
        ixx="0.00681707376598388"
        ixy="-9.55906063032647E-12"
        ixz="5.05760325058508E-11"
        iyy="0.00391273673603705"
        iyz="0.000445604816093975"
        izz="0.0049573253595571" />
    </inertial>
    <visual>
      <origin
        xyz="0 0 0"
        rpy="0 0 0" />
      <geometry>
        <mesh
          filename="package://arm_sim_node/urdf/meshes/link2.STL" />
      </geometry>
      <material
        name="">
        <color
          rgba="0.898039215686275 0.917647058823529 0.929411764705882 1" />
      </material>
    </visual>
    <collision>
      <origin
        xyz="0 0 0"
        rpy="0 0 0" />
      <geometry>
        <mesh
          filename="package://arm_sim_node/urdf/meshes/link2.STL" />
      </geometry>
    </collision>
  </link>
  <joint
    name="joint2"
    type="revolute">
    <origin
      xyz="0.0377 0 0.145"
      rpy="1.5707963267949 0 1.5707963267949" />
    <parent
      link="link1" />
    <child
      link="link2" />
    <axis
      xyz="0 0 1" />
    <limit
      lower="-2.3"
      upper="2.3"
      effort="100"
      velocity="100" />
  </joint>
  <link
    name="link2_sensor1_link">
    <inertial>
      <origin
        xyz="-0.000228568543839791 7.19703164022628E-07 0.0112564931324916"
        rpy="0 0 0" />
      <mass
        value="0.0280853097776281" />
      <inertia
        ixx="4.32261598928483E-06"
        ixy="3.04829332274897E-08"
        ixz="1.61957363513343E-08"
        iyy="4.26727737514081E-06"
        iyz="1.00050856908896E-11"
        izz="6.1259453751771E-06" />
    </inertial>
    <visual>
      <origin
        xyz="0 0 0"
        rpy="0 0 0" />
      <geometry>
        <mesh
          filename="package://arm_sim_node/urdf/meshes/link2_sensor1_link.STL" />
      </geometry>
      <material
        name="">
        <color
          rgba="0.898039215686275 0.917647058823529 0.929411764705882 1" />
      </material>
    </visual>
    <collision>
      <origin
        xyz="0 0 0"
        rpy="0 0 0" />
      <geometry>
        <mesh
          filename="package://arm_sim_node/urdf/meshes/link2_sensor1_link.STL" />
      </geometry>
    </collision>
  </link>
  <joint
    name="link2_sensor1_joint"
    type="fixed">
    <origin
      xyz="-0.0169999999999999 0.109 -0.0376999999999998"
      rpy="1.5707963267949 0 -1.57079632679489" />
    <parent
      link="link2" />
    <child
      link="link2_sensor1_link" />
    <axis
      xyz="0 0 0" />
  </joint>
  <link
    name="link2_sensor1_camera_link">
    <inertial>
      <origin
        xyz="0.0110000000000001 -1.69742692124331E-15 -0.0795000000000007"
        rpy="0 0 0" />
      <mass
        value="6.36172512351934E-05" />
      <inertia
        ixx="3.27363771981099E-10"
        ixy="-1.93870456067121E-27"
        ixz="-5.33929441248023E-25"
        iyy="3.27363771981099E-10"
        iyz="-6.76824924443896E-25"
        izz="6.44124668756333E-10" />
    </inertial>
    <visual>
      <origin
        xyz="0 0 0"
        rpy="0 0 0" />
      <geometry>
        <mesh
          filename="package://arm_sim_node/urdf/meshes/link2_sensor1_camera_link.STL" />
      </geometry>
      <material
        name="">
        <color
          rgba="0.898039215686275 0.917647058823529 0.929411764705882 1" />
      </material>
    </visual>
    <collision>
      <origin
        xyz="0 0 0"
        rpy="0 0 0" />
      <geometry>
        <mesh
          filename="package://arm_sim_node/urdf/meshes/link2_sensor1_camera_link.STL" />
      </geometry>
    </collision>
  </link>
  <joint
    name="link2_sensor1_camera_joint"
    type="fixed">
    <origin
      xyz="-0.0055 0.0055 -0.057"
      rpy="-3.1416 0 -1.5708" />
    <parent
      link="link2_sensor1_link" />
    <child
      link="link2_sensor1_camera_link" />
    <axis
      xyz="0 0 0" />
  </joint>
  <link
    name="link2_sensor1_tof_link">
    <inertial>
      <origin
        xyz="-0.011 -1.76681586028238E-15 -0.0795000000000007"
        rpy="0 0 0" />
      <mass
        value="6.36172512351934E-05" />
      <inertia
        ixx="3.27363771981099E-10"
        ixy="-1.93870456067121E-27"
        ixz="-5.33929441248023E-25"
        iyy="3.27363771981099E-10"
        iyz="-6.76824924443896E-25"
        izz="6.44124668756333E-10" />
    </inertial>
    <visual>
      <origin
        xyz="0 0 0"
        rpy="0 0 0" />
      <geometry>
        <mesh
          filename="package://arm_sim_node/urdf/meshes/link2_sensor1_tof_link.STL" />
      </geometry>
      <material
        name="">
        <color
          rgba="0.898039215686275 0.917647058823529 0.929411764705882 1" />
      </material>
    </visual>
    <collision>
      <origin
        xyz="0 0 0"
        rpy="0 0 0" />
      <geometry>
        <mesh
          filename="package://arm_sim_node/urdf/meshes/link2_sensor1_tof_link.STL" />
      </geometry>
    </collision>
  </link>
  <joint
    name="link2_sensor1_tof_joint"
    type="fixed">
    <origin
      xyz="0.0055 -0.0055 -0.057"
      rpy="-3.1416 0 -1.5708" />
    <parent
      link="link2_sensor1_link" />
    <child
      link="link2_sensor1_tof_link" />
    <axis
      xyz="0 0 0" />
  </joint>
  <link
    name="link2_sensor2_link">
    <inertial>
      <origin
        xyz="-0.000228568543839958 7.19703164025031E-07 0.0112564931324908"
        rpy="0 0 0" />
      <mass
        value="0.0280853097776282" />
      <inertia
        ixx="4.32261598928483E-06"
        ixy="3.04829332274879E-08"
        ixz="1.61957363513346E-08"
        iyy="4.26727737514082E-06"
        iyz="1.00050856903382E-11"
        izz="6.12594537517711E-06" />
    </inertial>
    <visual>
      <origin
        xyz="0 0 0"
        rpy="0 0 0" />
      <geometry>
        <mesh
          filename="package://arm_sim_node/urdf/meshes/link2_sensor2_link.STL" />
      </geometry>
      <material
        name="">
        <color
          rgba="0.898039215686275 0.917647058823529 0.929411764705882 1" />
      </material>
    </visual>
    <collision>
      <origin
        xyz="0 0 0"
        rpy="0 0 0" />
      <geometry>
        <mesh
          filename="package://arm_sim_node/urdf/meshes/link2_sensor2_link.STL" />
      </geometry>
    </collision>
  </link>
  <joint
    name="link2_sensor2_joint"
    type="fixed">
    <origin
      xyz="0.017 0.109 -0.0376999999999997"
      rpy="-1.5707963267949 0 -1.5707963267949" />
    <parent
      link="link2" />
    <child
      link="link2_sensor2_link" />
    <axis
      xyz="0 0 0" />
  </joint>
  <link
    name="link2_sensor2_camera_link">
    <inertial>
      <origin
        xyz="0.0110000000000002 -6.41847686111419E-17 -0.0794999999999999"
        rpy="0 0 0" />
      <mass
        value="6.36172512351934E-05" />
      <inertia
        ixx="3.27363771981099E-10"
        ixy="8.43471116152968E-27"
        ixz="-5.81651271751732E-25"
        iyy="3.27363771981099E-10"
        iyz="6.78108932832102E-25"
        izz="6.44124668756333E-10" />
    </inertial>
    <visual>
      <origin
        xyz="0 0 0"
        rpy="0 0 0" />
      <geometry>
        <mesh
          filename="package://arm_sim_node/urdf/meshes/link2_sensor2_camera_link.STL" />
      </geometry>
      <material
        name="">
        <color
          rgba="0.898039215686275 0.917647058823529 0.929411764705882 1" />
      </material>
    </visual>
    <collision>
      <origin
        xyz="0 0 0"
        rpy="0 0 0" />
      <geometry>
        <mesh
          filename="package://arm_sim_node/urdf/meshes/link2_sensor2_camera_link.STL" />
      </geometry>
    </collision>
  </link>
  <joint
    name="link2_sensor2_camera_joint"
    type="fixed">
    <origin
      xyz="-0.0055 0.0055 -0.057"
      rpy="-3.1416 0 -1.5708" />
    <parent
      link="link2_sensor2_link" />
    <child
      link="link2_sensor2_camera_link" />
    <axis
      xyz="0 0 0" />
  </joint>
  <link
    name="link2_sensor2_tof_link">
    <inertial>
      <origin
        xyz="-0.0109999999999999 -7.19910242530375E-17 -0.0794999999999999"
        rpy="0 0 0" />
      <mass
        value="6.36172512351934E-05" />
      <inertia
        ixx="3.27363771981099E-10"
        ixy="1.40959977432119E-26"
        ixz="-5.706961220746E-25"
        iyy="3.27363771981099E-10"
        iyz="6.72731604947771E-25"
        izz="6.44124668756333E-10" />
    </inertial>
    <visual>
      <origin
        xyz="0 0 0"
        rpy="0 0 0" />
      <geometry>
        <mesh
          filename="package://arm_sim_node/urdf/meshes/link2_sensor2_tof_link.STL" />
      </geometry>
      <material
        name="">
        <color
          rgba="0.898039215686275 0.917647058823529 0.929411764705882 1" />
      </material>
    </visual>
    <collision>
      <origin
        xyz="0 0 0"
        rpy="0 0 0" />
      <geometry>
        <mesh
          filename="package://arm_sim_node/urdf/meshes/link2_sensor2_tof_link.STL" />
      </geometry>
    </collision>
  </link>
  <joint
    name="link2_sensor2_tof_joint"
    type="fixed">
    <origin
      xyz="0.0055 -0.0055 -0.057"
      rpy="-3.1416 0 -1.5708" />
    <parent
      link="link2_sensor2_link" />
    <child
      link="link2_sensor2_tof_link" />
    <axis
      xyz="0 0 0" />
  </joint>
  <link
    name="link3">
    <inertial>
      <origin
        xyz="0.0382053785934682 2.69362486658608E-05 -0.116767542432942"
        rpy="0 0 0" />
      <mass
        value="0.582589401925533" />
      <inertia
        ixx="0.00217499498948574"
        ixy="-9.02828549174016E-08"
        ixz="0.000251445351988843"
        iyy="0.00207203135682847"
        iyz="2.44720534552963E-07"
        izz="0.000663505488104311" />
    </inertial>
    <visual>
      <origin
        xyz="0 0 0"
        rpy="0 0 0" />
      <geometry>
        <mesh
          filename="package://arm_sim_node/urdf/meshes/link3.STL" />
      </geometry>
      <material
        name="">
        <color
          rgba="0.898039215686275 0.917647058823529 0.929411764705882 1" />
      </material>
    </visual>
    <collision>
      <origin
        xyz="0 0 0"
        rpy="0 0 0" />
      <geometry>
        <mesh
          filename="package://arm_sim_node/urdf/meshes/link3.STL" />
      </geometry>
    </collision>
  </link>
  <joint
    name="joint3"
    type="revolute">
    <origin
      xyz="0 0.142 -0.0377000000000009"
      rpy="1.5707963267949 -1.5707963267949 0" />
    <parent
      link="link2" />
    <child
      link="link3" />
    <axis
      xyz="0 0 1" />
    <limit
      lower="-3.14"
      upper="3.14"
      effort="100"
      velocity="100" />
  </joint>
  <link
    name="link3_sensor1_link">
    <inertial>
      <origin
        xyz="0.000228568543840069 -7.19703164013025E-07 0.0112564931324908"
        rpy="0 0 0" />
      <mass
        value="0.0280853097776282" />
      <inertia
        ixx="4.32261598928483E-06"
        ixy="3.04829332274915E-08"
        ixz="-1.61957363513331E-08"
        iyy="4.26727737514081E-06"
        iyz="-1.00050856909277E-11"
        izz="6.1259453751771E-06" />
    </inertial>
    <visual>
      <origin
        xyz="0 0 0"
        rpy="0 0 0" />
      <geometry>
        <mesh
          filename="package://arm_sim_node/urdf/meshes/link3_sensor1_link.STL" />
      </geometry>
      <material
        name="">
        <color
          rgba="0.898039215686275 0.917647058823529 0.929411764705882 1" />
      </material>
    </visual>
    <collision>
      <origin
        xyz="0 0 0"
        rpy="0 0 0" />
      <geometry>
        <mesh
          filename="package://arm_sim_node/urdf/meshes/link3_sensor1_link.STL" />
      </geometry>
    </collision>
  </link>
  <joint
    name="link3_sensor1_joint"
    type="fixed">
    <origin
      xyz="0.0630000000000012 0 -0.13425"
      rpy="0 1.5707963267949 0" />
    <parent
      link="link3" />
    <child
      link="link3_sensor1_link" />
    <axis
      xyz="0 0 0" />
  </joint>
  <link
    name="link3_sensor1_camera_link">
    <inertial>
      <origin
        xyz="0.0109999999999992 0.0110000000000008 -0.000500000000002679"
        rpy="0 0 0" />
      <mass
        value="6.36172512351934E-05" />
      <inertia
        ixx="3.27363771981099E-10"
        ixy="-5.61705979896003E-36"
        ixz="-1.81923992016045E-24"
        iyy="3.27363771981099E-10"
        iyz="2.95134985728526E-26"
        izz="6.44124668756333E-10" />
    </inertial>
    <visual>
      <origin
        xyz="0 0 0"
        rpy="0 0 0" />
      <geometry>
        <mesh
          filename="package://arm_sim_node/urdf/meshes/link3_sensor1_camera_link.STL" />
      </geometry>
      <material
        name="">
        <color
          rgba="0.898039215686275 0.917647058823529 0.929411764705882 1" />
      </material>
    </visual>
    <collision>
      <origin
        xyz="0 0 0"
        rpy="0 0 0" />
      <geometry>
        <mesh
          filename="package://arm_sim_node/urdf/meshes/link3_sensor1_camera_link.STL" />
      </geometry>
    </collision>
  </link>
  <joint
    name="link3_sensor1_camera_joint"
    type="fixed">
    <origin
      xyz="0.0055 0.0055 0.023"
      rpy="0 0 -1.5708" />
    <parent
      link="link3_sensor1_link" />
    <child
      link="link3_sensor1_camera_link" />
    <axis
      xyz="0 0 0" />
  </joint>
  <link
    name="link3_sensor1_tof_link">
    <inertial>
      <origin
        xyz="-0.0110000000000008 -0.0109999999999992 -0.00050000000000272"
        rpy="0 0 0" />
      <mass
        value="6.36172512351934E-05" />
      <inertia
        ixx="3.27363771981099E-10"
        ixy="-7.22194249150602E-36"
        ixz="-1.81923992016045E-24"
        iyy="3.27363771981099E-10"
        iyz="2.95134985728527E-26"
        izz="6.44124668756333E-10" />
    </inertial>
    <visual>
      <origin
        xyz="0 0 0"
        rpy="0 0 0" />
      <geometry>
        <mesh
          filename="package://arm_sim_node/urdf/meshes/link3_sensor1_tof_link.STL" />
      </geometry>
      <material
        name="">
        <color
          rgba="0.898039215686275 0.917647058823529 0.929411764705882 1" />
      </material>
    </visual>
    <collision>
      <origin
        xyz="0 0 0"
        rpy="0 0 0" />
      <geometry>
        <mesh
          filename="package://arm_sim_node/urdf/meshes/link3_sensor1_tof_link.STL" />
      </geometry>
    </collision>
  </link>
  <joint
    name="link3_sensor1_tof_joint"
    type="fixed">
    <origin
      xyz="-0.0055 -0.0055 0.023"
      rpy="0 0 -1.5708" />
    <parent
      link="link3_sensor1_link" />
    <child
      link="link3_sensor1_tof_link" />
    <axis
      xyz="0 0 0" />
  </joint>
  <link
    name="link3_sensor2_link">
    <inertial>
      <origin
        xyz="-0.000228568543840019 7.19703164009378E-07 0.0112564931324908"
        rpy="0 0 0" />
      <mass
        value="0.0280853097776282" />
      <inertia
        ixx="4.32261598928483E-06"
        ixy="3.04829332274916E-08"
        ixz="1.61957363513339E-08"
        iyy="4.26727737514082E-06"
        iyz="1.00050856902153E-11"
        izz="6.1259453751771E-06" />
    </inertial>
    <visual>
      <origin
        xyz="0 0 0"
        rpy="0 0 0" />
      <geometry>
        <mesh
          filename="package://arm_sim_node/urdf/meshes/link3_sensor2_link.STL" />
      </geometry>
      <material
        name="">
        <color
          rgba="0.898039215686275 0.917647058823529 0.929411764705882 1" />
      </material>
    </visual>
    <collision>
      <origin
        xyz="0 0 0"
        rpy="0 0 0" />
      <geometry>
        <mesh
          filename="package://arm_sim_node/urdf/meshes/link3_sensor2_link.STL" />
      </geometry>
    </collision>
  </link>
  <joint
    name="link3_sensor2_joint"
    type="fixed">
    <origin
      xyz="0.000750000000001142 0 -0.13425"
      rpy="1.5707963267949 0 -1.5707963267949" />
    <parent
      link="link3" />
    <child
      link="link3_sensor2_link" />
    <axis
      xyz="0 0 0" />
  </joint>
  <link
    name="link3_sensor2_camera_link">
    <inertial>
      <origin
        xyz="0.011 0.0110000000000002 -0.0005"
        rpy="0 0 0" />
      <mass
        value="6.36172512351934E-05" />
      <inertia
        ixx="3.27363771981099E-10"
        ixy="-5.61715111214638E-36"
        ixz="-4.65284445336328E-26"
        iyy="3.27363771981099E-10"
        iyz="-6.84538804295522E-27"
        izz="6.44124668756332E-10" />
    </inertial>
    <visual>
      <origin
        xyz="0 0 0"
        rpy="0 0 0" />
      <geometry>
        <mesh
          filename="package://arm_sim_node/urdf/meshes/link3_sensor2_camera_link.STL" />
      </geometry>
      <material
        name="">
        <color
          rgba="0.898039215686275 0.917647058823529 0.929411764705882 1" />
      </material>
    </visual>
    <collision>
      <origin
        xyz="0 0 0"
        rpy="0 0 0" />
      <geometry>
        <mesh
          filename="package://arm_sim_node/urdf/meshes/link3_sensor2_camera_link.STL" />
      </geometry>
    </collision>
  </link>
  <joint
    name="link3_sensor2_camera_joint"
    type="fixed">
    <origin
      xyz="-0.0055 -0.0055 0.023"
      rpy="0 0 1.5708" />
    <parent
      link="link3_sensor2_link" />
    <child
      link="link3_sensor2_camera_link" />
    <axis
      xyz="0 0 0" />
  </joint>
  <link
    name="link3_sensor2_tof_link">
    <inertial>
      <origin
        xyz="-0.011 -0.011 -0.000500000000000004"
        rpy="0 0 0" />
      <mass
        value="6.36172512351934E-05" />
      <inertia
        ixx="3.27363771981099E-10"
        ixy="-7.22210268131449E-36"
        ixz="-4.65284445336328E-26"
        iyy="3.27363771981099E-10"
        iyz="-6.84538804295522E-27"
        izz="6.44124668756332E-10" />
    </inertial>
    <visual>
      <origin
        xyz="0 0 0"
        rpy="0 0 0" />
      <geometry>
        <mesh
          filename="package://arm_sim_node/urdf/meshes/link3_sensor2_tof_link.STL" />
      </geometry>
      <material
        name="">
        <color
          rgba="0.898039215686275 0.917647058823529 0.929411764705882 1" />
      </material>
    </visual>
    <collision>
      <origin
        xyz="0 0 0"
        rpy="0 0 0" />
      <geometry>
        <mesh
          filename="package://arm_sim_node/urdf/meshes/link3_sensor2_tof_link.STL" />
      </geometry>
    </collision>
  </link>
  <joint
    name="link3_sensor2_tof_joint"
    type="fixed">
    <origin
      xyz="0.0055 0.0055 0.023"
      rpy="0 0 1.5708" />
    <parent
      link="link3_sensor2_link" />
    <child
      link="link3_sensor2_tof_link" />
    <axis
      xyz="0 0 0" />
  </joint>
  <link
    name="link4">
    <inertial>
      <origin
        xyz="-1.96484668744606E-05 -0.0695934964300845 -0.0527490114772609"
        rpy="0 0 0" />
      <mass
        value="0.499691951248306" />
      <inertia
        ixx="0.00118224707570711"
        ixy="-1.42437858818239E-07"
        ixz="-1.88226425968712E-07"
        iyy="0.000347696574337866"
        iyz="0.000112751754317425"
        izz="0.00134960905730777" />
    </inertial>
    <visual>
      <origin
        xyz="0 0 0"
        rpy="0 0 0" />
      <geometry>
        <mesh
          filename="package://arm_sim_node/urdf/meshes/link4.STL" />
      </geometry>
      <material
        name="">
        <color
          rgba="0.898039215686275 0.917647058823529 0.929411764705882 1" />
      </material>
    </visual>
    <collision>
      <origin
        xyz="0 0 0"
        rpy="0 0 0" />
      <geometry>
        <mesh
          filename="package://arm_sim_node/urdf/meshes/link4.STL" />
      </geometry>
    </collision>
  </link>
  <joint
    name="joint4"
    type="revolute">
    <origin
      xyz="0.0450000000000012 0 -0.21125"
      rpy="1.5707963267949 0 1.5707963267949" />
    <parent
      link="link3" />
    <child
      link="link4" />
    <axis
      xyz="0 0 1" />
    <limit
      lower="-2.65"
      upper="2.65"
      effort="100"
      velocity="100" />
  </joint>
  <link
    name="link4_sensor1_link">
    <inertial>
      <origin
        xyz="0.000228568543840008 -7.19703163953866E-07 0.0112564931324908"
        rpy="0 0 0" />
      <mass
        value="0.0280853097776281" />
      <inertia
        ixx="4.32261598928481E-06"
        ixy="3.04829332274935E-08"
        ixz="-1.61957363513329E-08"
        iyy="4.26727737514082E-06"
        iyz="-1.00050856922343E-11"
        izz="6.12594537517709E-06" />
    </inertial>
    <visual>
      <origin
        xyz="0 0 0"
        rpy="0 0 0" />
      <geometry>
        <mesh
          filename="package://arm_sim_node/urdf/meshes/link4_sensor1_link.STL" />
      </geometry>
      <material
        name="">
        <color
          rgba="0.898039215686275 0.917647058823529 0.929411764705882 1" />
      </material>
    </visual>
    <collision>
      <origin
        xyz="0 0 0"
        rpy="0 0 0" />
      <geometry>
        <mesh
          filename="package://arm_sim_node/urdf/meshes/link4_sensor1_link.STL" />
      </geometry>
    </collision>
  </link>
  <joint
    name="link4_sensor1_joint"
    type="fixed">
    <origin
      xyz="-0.010000000000001 -0.115 -0.042249999999998"
      rpy="3.14159265358979 1.5707963267949 0" />
    <parent
      link="link4" />
    <child
      link="link4_sensor1_link" />
    <axis
      xyz="0 0 0" />
  </joint>
  <link
    name="link4_sensor1_camera_link">
    <inertial>
      <origin
        xyz="0.0110000000000053 0.0110000000000006 -0.000499999999999931"
        rpy="0 0 0" />
      <mass
        value="6.36172512351933E-05" />
      <inertia
        ixx="3.27363771981099E-10"
        ixy="-7.36270178218522E-31"
        ixz="-7.50047434365883E-28"
        iyy="3.27363771981099E-10"
        iyz="1.22964181563149E-25"
        izz="6.44124668756332E-10" />
    </inertial>
    <visual>
      <origin
        xyz="0 0 0"
        rpy="0 0 0" />
      <geometry>
        <mesh
          filename="package://arm_sim_node/urdf/meshes/link4_sensor1_camera_link.STL" />
      </geometry>
      <material
        name="">
        <color
          rgba="0.898039215686275 0.917647058823529 0.929411764705882 1" />
      </material>
    </visual>
    <collision>
      <origin
        xyz="0 0 0"
        rpy="0 0 0" />
      <geometry>
        <mesh
          filename="package://arm_sim_node/urdf/meshes/link4_sensor1_camera_link.STL" />
      </geometry>
    </collision>
  </link>
  <joint
    name="link4_sensor1_camera_joint"
    type="fixed">
    <origin
      xyz="0.0055 0.0055 0.023"
      rpy="0 0 -1.5708" />
    <parent
      link="link4_sensor1_link" />
    <child
      link="link4_sensor1_camera_link" />
    <axis
      xyz="0 0 0" />
  </joint>
  <link
    name="link4_sensor1_tof_link">
    <inertial>
      <origin
        xyz="-0.0109999999999942 -0.0109999999999999 -0.00050000000000007"
        rpy="0 0 0" />
      <mass
        value="6.36172512351934E-05" />
      <inertia
        ixx="3.27363771981099E-10"
        ixy="-8.56242774233129E-31"
        ixz="9.72098268996497E-28"
        iyy="3.27363771981099E-10"
        iyz="5.18684159067175E-26"
        izz="6.44124668756332E-10" />
    </inertial>
    <visual>
      <origin
        xyz="0 0 0"
        rpy="0 0 0" />
      <geometry>
        <mesh
          filename="package://arm_sim_node/urdf/meshes/link4_sensor1_tof_link.STL" />
      </geometry>
      <material
        name="">
        <color
          rgba="0.898039215686275 0.917647058823529 0.929411764705882 1" />
      </material>
    </visual>
    <collision>
      <origin
        xyz="0 0 0"
        rpy="0 0 0" />
      <geometry>
        <mesh
          filename="package://arm_sim_node/urdf/meshes/link4_sensor1_tof_link.STL" />
      </geometry>
    </collision>
  </link>
  <joint
    name="link4_sensor1_tof_joint"
    type="fixed">
    <origin
      xyz="-0.0055 -0.0055 0.023"
      rpy="0 0 -1.5708" />
    <parent
      link="link4_sensor1_link" />
    <child
      link="link4_sensor1_tof_link" />
    <axis
      xyz="0 0 0" />
  </joint>
  <link
    name="link4_sensor2_link">
    <inertial>
      <origin
        xyz="-0.000228568543839791 7.19703161042133E-07 0.0112564931324909"
        rpy="0 0 0" />
      <mass
        value="0.0280853097776282" />
      <inertia
        ixx="4.32261598928484E-06"
        ixy="3.04829332274894E-08"
        ixz="1.61957363513335E-08"
        iyy="4.26727737514083E-06"
        iyz="1.00050856908473E-11"
        izz="6.12594537517712E-06" />
    </inertial>
    <visual>
      <origin
        xyz="0 0 0"
        rpy="0 0 0" />
      <geometry>
        <mesh
          filename="package://arm_sim_node/urdf/meshes/link4_sensor2_link.STL" />
      </geometry>
      <material
        name="">
        <color
          rgba="0.898039215686275 0.917647058823529 0.929411764705882 1" />
      </material>
    </visual>
    <collision>
      <origin
        xyz="0 0 0"
        rpy="0 0 0" />
      <geometry>
        <mesh
          filename="package://arm_sim_node/urdf/meshes/link4_sensor2_link.STL" />
      </geometry>
    </collision>
  </link>
  <joint
    name="link4_sensor2_joint"
    type="fixed">
    <origin
      xyz="0.00999999999999898 -0.115 -0.0422499999999997"
      rpy="-1.5707963267949 0 -1.5707963267949" />
    <parent
      link="link4" />
    <child
      link="link4_sensor2_link" />
    <axis
      xyz="0 0 0" />
  </joint>
  <link
    name="link4_sensor2_camera_link">
    <inertial>
      <origin
        xyz="0.0109999999999998 0.011 -0.000499999999999994"
        rpy="0 0 0" />
      <mass
        value="6.36172512351934E-05" />
      <inertia
        ixx="3.27363771981099E-10"
        ixy="-1.05181454022198E-30"
        ixz="-3.64035083444701E-26"
        iyy="3.27363771981099E-10"
        iyz="-7.45581236687719E-27"
        izz="6.44124668756332E-10" />
    </inertial>
    <visual>
      <origin
        xyz="0 0 0"
        rpy="0 0 0" />
      <geometry>
        <mesh
          filename="package://arm_sim_node/urdf/meshes/link4_sensor2_camera_link.STL" />
      </geometry>
      <material
        name="">
        <color
          rgba="0.898039215686275 0.917647058823529 0.929411764705882 1" />
      </material>
    </visual>
    <collision>
      <origin
        xyz="0 0 0"
        rpy="0 0 0" />
      <geometry>
        <mesh
          filename="package://arm_sim_node/urdf/meshes/link4_sensor2_camera_link.STL" />
      </geometry>
    </collision>
  </link>
  <joint
    name="link4_sensor2_camera_joint"
    type="fixed">
    <origin
      xyz="-0.0055 -0.0055 0.023"
      rpy="0 0 1.5708" />
    <parent
      link="link4_sensor2_link" />
    <child
      link="link4_sensor2_camera_link" />
    <axis
      xyz="0 0 0" />
  </joint>
  <link
    name="link4_sensor2_tof_link">
    <inertial>
      <origin
        xyz="-0.011 -0.011 -0.000500000000000028"
        rpy="0 0 0" />
      <mass
        value="6.36172512351933E-05" />
      <inertia
        ixx="3.27363771981099E-10"
        ixy="7.06687894273882E-31"
        ixz="7.01585039963243E-26"
        iyy="3.27363771981099E-10"
        iyz="1.15931951675464E-27"
        izz="6.44124668756332E-10" />
    </inertial>
    <visual>
      <origin
        xyz="0 0 0"
        rpy="0 0 0" />
      <geometry>
        <mesh
          filename="package://arm_sim_node/urdf/meshes/link4_sensor2_tof_link.STL" />
      </geometry>
      <material
        name="">
        <color
          rgba="0.898039215686275 0.917647058823529 0.929411764705882 1" />
      </material>
    </visual>
    <collision>
      <origin
        xyz="0 0 0"
        rpy="0 0 0" />
      <geometry>
        <mesh
          filename="package://arm_sim_node/urdf/meshes/link4_sensor2_tof_link.STL" />
      </geometry>
    </collision>
  </link>
  <joint
    name="link4_sensor2_tof_joint"
    type="fixed">
    <origin
      xyz="0.0055 0.0055 0.023"
      rpy="0 0 1.5708" />
    <parent
      link="link4_sensor2_link" />
    <child
      link="link4_sensor2_tof_link" />
    <axis
      xyz="0 0 0" />
  </joint>
  <link
    name="wrist_link1">
    <inertial>
      <origin
        xyz="0.00352707839199187 -5.046664839529E-05 0.0556606367218427"
        rpy="0 0 0" />
      <mass
        value="0.165249310681186" />
      <inertia
        ixx="0.000101827092950677"
        ixy="-6.96700678035003E-08"
        ixz="2.67501088034374E-07"
        iyy="0.00010977530285432"
        iyz="-2.71303548325022E-08"
        izz="8.59339042614574E-05" />
    </inertial>
    <visual>
      <origin
        xyz="0 0 0"
        rpy="0 0 0" />
      <geometry>
        <mesh
          filename="package://arm_sim_node/urdf/meshes/wrist_link1.STL" />
      </geometry>
      <material
        name="">
        <color
          rgba="0.898039215686275 0.917647058823529 0.929411764705882 1" />
      </material>
    </visual>
    <collision>
      <origin
        xyz="0 0 0"
        rpy="0 0 0" />
      <geometry>
        <mesh
          filename="package://arm_sim_node/urdf/meshes/wrist_link1.STL" />
      </geometry>
    </collision>
  </link>
  <joint
    name="wrist_joint1"
    type="revolute">
    <origin
      xyz="0 -0.22525 -0.0449999999999971"
      rpy="1.5707963267949 -1.5707963267949 0" />
    <parent
      link="link4" />
    <child
      link="wrist_link1" />
    <axis
      xyz="0 0 1" />
    <limit
      lower="-3.14"
      upper="3.14"
      effort="100"
      velocity="100" />
  </joint>
  <link
    name="wrist_link2">
    <inertial>
      <origin
        xyz="0.0032749201170947 3.6174834796121E-05 -0.0352410752787541"
        rpy="0 0 0" />
      <mass
        value="0.113563263335891" />
      <inertia
        ixx="8.22056606936563E-05"
        ixy="4.11957711935237E-08"
        ixz="1.81514767243925E-07"
        iyy="6.24860697352306E-05"
        iyz="-1.06157282031961E-06"
        izz="5.9966239536844E-05" />
    </inertial>
    <visual>
      <origin
        xyz="0 0 0"
        rpy="0 0 0" />
      <geometry>
        <mesh
          filename="package://arm_sim_node/urdf/meshes/wrist_link2.STL" />
      </geometry>
      <material
        name="">
        <color
          rgba="0.898039215686275 0.917647058823529 0.929411764705882 1" />
      </material>
    </visual>
    <collision>
      <origin
        xyz="0 0 0"
        rpy="0 0 0" />
      <geometry>
        <mesh
          filename="package://arm_sim_node/urdf/meshes/wrist_link2.STL" />
      </geometry>
    </collision>
  </link>
  <joint
    name="wrist_joint2"
    type="revolute">
    <origin
      xyz="0.03549999993081 0 0.134999999945961"
      rpy="-1.5707963267949 0 -1.5707963267949" />
    <parent
      link="wrist_link1" />
    <child
      link="wrist_link2" />
    <axis
      xyz="0 0 1" />
    <limit
      lower="-3.14"
      upper="3.14"
      effort="100"
      velocity="100" />
  </joint>
  <link
    name="wrist_link3">
    <inertial>
      <origin
        xyz="0.000122260474742749 -0.033008042147523 -0.0093146869027906"
        rpy="0 0 0" />
      <mass
        value="0.0627633465287199" />
      <inertia
        ixx="4.2581565184529E-05"
        ixy="1.38030805624568E-06"
        ixz="3.79394638543889E-11"
        iyy="3.50631826362204E-05"
        iyz="-1.11183612133598E-05"
        izz="4.62054718437767E-05" />
    </inertial>
    <visual>
      <origin
        xyz="0 0 0"
        rpy="0 0 0" />
      <geometry>
        <mesh
          filename="package://arm_sim_node/urdf/meshes/wrist_link3.STL" />
      </geometry>
      <material
        name="">
        <color
          rgba="0.898039215686275 0.917647058823529 0.929411764705882 1" />
      </material>
    </visual>
    <collision>
      <origin
        xyz="0 0 0"
        rpy="0 0 0" />
      <geometry>
        <mesh
          filename="package://arm_sim_node/urdf/meshes/wrist_link3.STL" />
      </geometry>
    </collision>
  </link>
  <joint
    name="wrist_joint3"
    type="revolute">
    <origin
      xyz="0.0256250000410695 0 -0.0354999999325699"
      rpy="0 1.5707963267949 0" />
    <parent
      link="wrist_link2" />
    <child
      link="wrist_link3" />
    <axis
      xyz="0 0 1" />
    <limit
      lower="-1.2"
      upper="1.2"
      effort="100"
      velocity="100" />
  </joint>
  <link
    name="EE_sensor1_link">
    <inertial>
      <origin
        xyz="-0.00022856854384002 7.19703162606089E-07 0.0112564931324906"
        rpy="0 0 0" />
      <mass
        value="0.0280853097776282" />
      <inertia
        ixx="4.32261598928482E-06"
        ixy="3.04829332274869E-08"
        ixz="1.6195736351333E-08"
        iyy="4.26727737514081E-06"
        iyz="1.00050856919219E-11"
        izz="6.1259453751771E-06" />
    </inertial>
    <visual>
      <origin
        xyz="0 0 0"
        rpy="0 0 0" />
      <geometry>
        <mesh
          filename="package://arm_sim_node/urdf/meshes/EE_sensor1_link.STL" />
      </geometry>
      <material
        name="">
        <color
          rgba="0.898039215686275 0.917647058823529 0.929411764705882 1" />
      </material>
    </visual>
    <collision>
      <origin
        xyz="0 0 0"
        rpy="0 0 0" />
      <geometry>
        <mesh
          filename="package://arm_sim_node/urdf/meshes/EE_sensor1_link.STL" />
      </geometry>
    </collision>
  </link>
  <joint
    name="EE_sensor1_joint"
    type="fixed">
    <origin
      xyz="0.04525 -0.041 -0.025625"
      rpy="1.5708 0 0" />
    <parent
      link="wrist_link3" />
    <child
      link="EE_sensor1_link" />
    <axis
      xyz="0 0 0" />
  </joint>
  <link
    name="EE_sensor1_camera_link">
    <inertial>
      <origin
        xyz="0.0110000000009206 0.0109999999999828 -0.00049999997474548"
        rpy="0 0 0" />
      <mass
        value="6.36172512351934E-05" />
      <inertia
        ixx="3.27363771981099E-10"
        ixy="1.0339757656787E-26"
        ixz="-8.53954676984747E-26"
        iyy="3.27363771981099E-10"
        iyz="-2.12272920930759E-27"
        izz="6.44124668756333E-10" />
    </inertial>
    <visual>
      <origin
        xyz="0 0 0"
        rpy="0 0 0" />
      <geometry>
        <mesh
          filename="package://arm_sim_node/urdf/meshes/EE_sensor1_camera_link.STL" />
      </geometry>
      <material
        name="">
        <color
          rgba="0.898039215686275 0.917647058823529 0.929411764705882 1" />
      </material>
    </visual>
    <collision>
      <origin
        xyz="0 0 0"
        rpy="0 0 0" />
      <geometry>
        <mesh
          filename="package://arm_sim_node/urdf/meshes/EE_sensor1_camera_link.STL" />
      </geometry>
    </collision>
  </link>
  <joint
    name="EE_sensor1_camera_joint"
    type="fixed">
    <origin
      xyz="-0.0055 -0.0055 0.023"
      rpy="0 0 1.5708" />
    <parent
      link="EE_sensor1_link" />
    <child
      link="EE_sensor1_camera_link" />
    <axis
      xyz="0 0 0" />
  </joint>
  <link
    name="EE_sensor1_tof_link">
    <inertial>
      <origin
        xyz="-0.0109999999990793 -0.011000000000017 -0.000499999974745702"
        rpy="0 0 0" />
      <mass
        value="6.36172512351934E-05" />
      <inertia
        ixx="3.27363771981099E-10"
        ixy="1.02185886217505E-26"
        ixz="2.27283124901765E-26"
        iyy="3.27363771981099E-10"
        iyz="1.28243293401167E-27"
        izz="6.44124668756333E-10" />
    </inertial>
    <visual>
      <origin
        xyz="0 0 0"
        rpy="0 0 0" />
      <geometry>
        <mesh
          filename="package://arm_sim_node/urdf/meshes/EE_sensor1_tof_link.STL" />
      </geometry>
      <material
        name="">
        <color
          rgba="0.898039215686275 0.917647058823529 0.929411764705882 1" />
      </material>
    </visual>
    <collision>
      <origin
        xyz="0 0 0"
        rpy="0 0 0" />
      <geometry>
        <mesh
          filename="package://arm_sim_node/urdf/meshes/EE_sensor1_tof_link.STL" />
      </geometry>
    </collision>
  </link>
  <joint
    name="EE_sensor1_tof_joint"
    type="fixed">
    <origin
      xyz="0.0055 0.0055 0.023"
      rpy="0 0 1.5708" />
    <parent
      link="EE_sensor1_link" />
    <child
      link="EE_sensor1_tof_link" />
    <axis
      xyz="0 0 0" />
  </joint>
  <link
    name="EE_snesor2_link">
    <inertial>
      <origin
        xyz="-0.000228568553391706 7.19703178335965E-07 0.0112564931558856"
        rpy="0 0 0" />
      <mass
        value="0.0280853097776281" />
      <inertia
        ixx="4.32261598928481E-06"
        ixy="3.0482933227487E-08"
        ixz="1.61957363513331E-08"
        iyy="4.2672773751408E-06"
        iyz="1.00050856914545E-11"
        izz="6.12594537517709E-06" />
    </inertial>
    <visual>
      <origin
        xyz="0 0 0"
        rpy="0 0 0" />
      <geometry>
        <mesh
          filename="package://arm_sim_node/urdf/meshes/EE_snesor2_link.STL" />
      </geometry>
      <material
        name="">
        <color
          rgba="0.898039215686275 0.917647058823529 0.929411764705882 1" />
      </material>
    </visual>
    <collision>
      <origin
        xyz="0 0 0"
        rpy="0 0 0" />
      <geometry>
        <mesh
          filename="package://arm_sim_node/urdf/meshes/EE_snesor2_link.STL" />
      </geometry>
    </collision>
  </link>
  <joint
    name="EE_snesor2_joint"
    type="fixed">
    <origin
      xyz="-0.043469 -0.031168 -0.025625"
      rpy="-1.5708 0 2.7925" />
    <parent
      link="wrist_link3" />
    <child
      link="EE_snesor2_link" />
    <axis
      xyz="0 0 0" />
  </joint>
  <link
    name="EE_sensor2_camera_link">
    <inertial>
      <origin
        xyz="0.0109999999904482 0.0110000000000138 -0.000499999976604992"
        rpy="0 0 0" />
      <mass
        value="6.36172512351907E-05" />
      <inertia
        ixx="3.27363771981085E-10"
        ixy="5.95705361328952E-26"
        ixz="-1.09859925104699E-25"
        iyy="3.27363771981085E-10"
        iyz="-1.77715364812103E-26"
        izz="6.44124668756305E-10" />
    </inertial>
    <visual>
      <origin
        xyz="0 0 0"
        rpy="0 0 0" />
      <geometry>
        <mesh
          filename="package://arm_sim_node/urdf/meshes/EE_sensor2_camera_link.STL" />
      </geometry>
      <material
        name="">
        <color
          rgba="0.898039215686275 0.917647058823529 0.929411764705882 1" />
      </material>
    </visual>
    <collision>
      <origin
        xyz="0 0 0"
        rpy="0 0 0" />
      <geometry>
        <mesh
          filename="package://arm_sim_node/urdf/meshes/EE_sensor2_camera_link.STL" />
      </geometry>
    </collision>
  </link>
  <joint
    name="EE_sensor2_camera_joint"
    type="fixed">
    <origin
      xyz="-0.0055 -0.0055 0.023"
      rpy="0 0 1.5708" />
    <parent
      link="EE_snesor2_link" />
    <child
      link="EE_sensor2_camera_link" />
    <axis
      xyz="0 0 0" />
  </joint>
  <link
    name="EE_sensor2_tof_link">
    <inertial>
      <origin
        xyz="-0.0110000000095517 -0.0109999999999862 -0.000499999976605103"
        rpy="0 0 0" />
      <mass
        value="6.36172512351907E-05" />
      <inertia
        ixx="3.27363771981085E-10"
        ixy="5.95705361328952E-26"
        ixz="-1.09859925104699E-25"
        iyy="3.27363771981085E-10"
        iyz="-1.77715364812103E-26"
        izz="6.44124668756305E-10" />
    </inertial>
    <visual>
      <origin
        xyz="0 0 0"
        rpy="0 0 0" />
      <geometry>
        <mesh
          filename="package://arm_sim_node/urdf/meshes/EE_sensor2_tof_link.STL" />
      </geometry>
      <material
        name="">
        <color
          rgba="0.898039215686275 0.917647058823529 0.929411764705882 1" />
      </material>
    </visual>
    <collision>
      <origin
        xyz="0 0 0"
        rpy="0 0 0" />
      <geometry>
        <mesh
          filename="package://arm_sim_node/urdf/meshes/EE_sensor2_tof_link.STL" />
      </geometry>
    </collision>
  </link>
  <joint
    name="EE_sensor2_tof_joint"
    type="fixed">
    <origin
      xyz="0.0055 0.0055 0.023"
      rpy="0 0 1.5708" />
    <parent
      link="EE_snesor2_link" />
    <child
      link="EE_sensor2_tof_link" />
    <axis
      xyz="0 0 0" />
  </joint>
  <link
    name="EE_link">
    <inertial>
      <origin
        xyz="-9.88108095342215E-13 2.01575405637501E-11 -0.000499999974748588"
        rpy="0 0 0" />
      <mass
        value="6.36172512351934E-05" />
      <inertia
        ixx="3.27363771981099E-10"
        ixy="6.89317177127566E-27"
        ixz="-1.93165075902025E-26"
        iyy="3.27363771981099E-10"
        iyz="9.5682948118006E-26"
        izz="6.44124668756332E-10" />
    </inertial>
    <visual>
      <origin
        xyz="0 0 0"
        rpy="0 0 0" />
      <geometry>
        <mesh
          filename="package://arm_sim_node/urdf/meshes/EE_link.STL" />
      </geometry>
      <material
        name="">
        <color
          rgba="0.898039215686275 0.917647058823529 0.929411764705882 1" />
      </material>
    </visual>
    <collision>
      <origin
        xyz="0 0 0"
        rpy="0 0 0" />
      <geometry>
        <mesh
          filename="package://arm_sim_node/urdf/meshes/EE_link.STL" />
      </geometry>
    </collision>
  </link>
  <joint
    name="EE_joint"
    type="fixed">
    <origin
      xyz="0 -0.053999999971988 -0.0256250000093045"
      rpy="-1.5707963267949 0 3.14159265358979" />
    <parent
      link="wrist_link3" />
    <child
      link="EE_link" />
    <axis
      xyz="0 0 0" />
  </joint>

  <!-- Gazebo rendering frames and MaixSense prototype sensors on link4.
       Existing camera/tof links are ROS optical frames: x image-right,
       y image-down, z viewing-forward. Gazebo rendering cameras view
       along positive x, so dedicated gz links supply the fixed rotation. -->

  <!-- link4_sensor1 rendering frames -->
  <link name="link4_sensor1_camera_gz_link">
    <!-- Massless links are removed during URDF-to-SDF conversion when the
         fixed joint is preserved. This tiny positive inertia keeps the
         dedicated Gazebo rendering frame and its attached sensor in SDF. -->
    <inertial>
      <origin xyz="0 0 0" rpy="0 0 0" />
      <mass value="0.000001" />
      <inertia
        ixx="0.000000001"
        ixy="0"
        ixz="0"
        iyy="0.000000001"
        iyz="0"
        izz="0.000000001" />
    </inertial>
  </link>
  <joint name="link4_sensor1_camera_gz_joint" type="fixed">
    <origin xyz="0 0 0" rpy="1.5707963267949 -1.5707963267949 0" />
    <parent link="link4_sensor1_camera_link" />
    <child link="link4_sensor1_camera_gz_link" />
    <axis xyz="0 0 0" />
  </joint>

  <link name="link4_sensor1_tof_gz_link">
    <!-- Massless links are removed during URDF-to-SDF conversion when the
         fixed joint is preserved. This tiny positive inertia keeps the
         dedicated Gazebo rendering frame and its attached sensor in SDF. -->
    <inertial>
      <origin xyz="0 0 0" rpy="0 0 0" />
      <mass value="0.000001" />
      <inertia
        ixx="0.000000001"
        ixy="0"
        ixz="0"
        iyy="0.000000001"
        iyz="0"
        izz="0.000000001" />
    </inertial>
  </link>
  <joint name="link4_sensor1_tof_gz_joint" type="fixed">
    <origin xyz="0 0 0" rpy="1.5707963267949 -1.5707963267949 0" />
    <parent link="link4_sensor1_tof_link" />
    <child link="link4_sensor1_tof_gz_link" />
    <axis xyz="0 0 0" />
  </joint>

  <!-- link4_sensor2 rendering frames -->
  <link name="link4_sensor2_camera_gz_link">
    <!-- Massless links are removed during URDF-to-SDF conversion when the
         fixed joint is preserved. This tiny positive inertia keeps the
         dedicated Gazebo rendering frame and its attached sensor in SDF. -->
    <inertial>
      <origin xyz="0 0 0" rpy="0 0 0" />
      <mass value="0.000001" />
      <inertia
        ixx="0.000000001"
        ixy="0"
        ixz="0"
        iyy="0.000000001"
        iyz="0"
        izz="0.000000001" />
    </inertial>
  </link>
  <joint name="link4_sensor2_camera_gz_joint" type="fixed">
    <origin xyz="0 0 0" rpy="1.5707963267949 -1.5707963267949 0" />
    <parent link="link4_sensor2_camera_link" />
    <child link="link4_sensor2_camera_gz_link" />
    <axis xyz="0 0 0" />
  </joint>

  <link name="link4_sensor2_tof_gz_link">
    <!-- Massless links are removed during URDF-to-SDF conversion when the
         fixed joint is preserved. This tiny positive inertia keeps the
         dedicated Gazebo rendering frame and its attached sensor in SDF. -->
    <inertial>
      <origin xyz="0 0 0" rpy="0 0 0" />
      <mass value="0.000001" />
      <inertia
        ixx="0.000000001"
        ixy="0"
        ixz="0"
        iyy="0.000000001"
        iyz="0"
        izz="0.000000001" />
    </inertial>
  </link>
  <joint name="link4_sensor2_tof_gz_joint" type="fixed">
    <origin xyz="0 0 0" rpy="1.5707963267949 -1.5707963267949 0" />
    <parent link="link4_sensor2_tof_link" />
    <child link="link4_sensor2_tof_gz_link" />
    <axis xyz="0 0 0" />
  </joint>

  <!-- Preserve the explicit Gazebo rendering-frame joints for inspection. -->
  <gazebo reference="link4_sensor1_camera_gz_joint">
    <preserveFixedJoint>true</preserveFixedJoint>
  </gazebo>
  <gazebo reference="link4_sensor1_tof_gz_joint">
    <preserveFixedJoint>true</preserveFixedJoint>
  </gazebo>
  <gazebo reference="link4_sensor2_camera_gz_joint">
    <preserveFixedJoint>true</preserveFixedJoint>
  </gazebo>
  <gazebo reference="link4_sensor2_tof_gz_joint">
    <preserveFixedJoint>true</preserveFixedJoint>
  </gazebo>

  <!-- link4_sensor1 RGB: ideal RGB observation only -->
  <gazebo reference="link4_sensor1_camera_gz_link">
    <sensor type="camera" name="link4_sensor1_rgb_sensor">
      <always_on>true</always_on>
      <update_rate>30.0</update_rate>
      <visualize>false</visualize>
      <camera name="link4_sensor1_rgb_camera">
        <horizontal_fov>2.0943951023932</horizontal_fov>
        <image>
          <width>800</width>
          <height>600</height>
          <format>R8G8B8</format>
        </image>
        <clip>
          <near>0.05</near>
          <far>5.0</far>
        </clip>
      </camera>
      <plugin name="link4_sensor1_rgb_ros_plugin" filename="libgazebo_ros_camera.so">
        <alwaysOn>true</alwaysOn>
        <updateRate>0.0</updateRate>
        <cameraName>link4_sensor1_rgb</cameraName>
        <imageTopicName>/link4_sensor1/rgb/image_raw</imageTopicName>
        <cameraInfoTopicName>/link4_sensor1/rgb/camera_info</cameraInfoTopicName>
        <frameName>link4_sensor1_camera_link</frameName>
        <distortionK1>0.0</distortionK1>
        <distortionK2>0.0</distortionK2>
        <distortionK3>0.0</distortionK3>
        <distortionT1>0.0</distortionT1>
        <distortionT2>0.0</distortionT2>
      </plugin>
    </sensor>
  </gazebo>

  <!-- link4_sensor1 ToF approximation: ideal depth plus PointCloud2 -->
  <gazebo reference="link4_sensor1_tof_gz_link">
    <sensor type="depth" name="link4_sensor1_tof_sensor">
      <always_on>true</always_on>
      <update_rate>30.0</update_rate>
      <visualize>false</visualize>
      <camera name="link4_sensor1_tof_camera">
        <horizontal_fov>0.9599310885968813</horizontal_fov>
        <image>
          <width>320</width>
          <height>240</height>
          <format>R8G8B8</format>
        </image>
        <clip>
          <near>0.15</near>
          <far>0.75</far>
        </clip>
      </camera>
      <plugin name="link4_sensor1_tof_ros_plugin" filename="libgazebo_ros_openni_kinect.so">
        <baseline>0.0</baseline>
        <alwaysOn>true</alwaysOn>
        <updateRate>0.0</updateRate>
        <cameraName>link4_sensor1_tof</cameraName>
        <imageTopicName>/link4_sensor1/tof/internal_rgb_unused/image_raw</imageTopicName>
        <cameraInfoTopicName>/link4_sensor1/tof/internal_rgb_unused/camera_info</cameraInfoTopicName>
        <depthImageTopicName>/link4_sensor1/tof/depth_raw</depthImageTopicName>
        <depthImageCameraInfoTopicName>/link4_sensor1/tof/camera_info</depthImageCameraInfoTopicName>
        <pointCloudTopicName>/link4_sensor1/tof/cloud</pointCloudTopicName>
        <frameName>link4_sensor1_tof_link</frameName>
        <pointCloudCutoff>0.15</pointCloudCutoff>
        <pointCloudCutoffMax>0.75</pointCloudCutoffMax>
      </plugin>
    </sensor>
  </gazebo>

  <!-- link4_sensor2 RGB: ideal RGB observation only -->
  <gazebo reference="link4_sensor2_camera_gz_link">
    <sensor type="camera" name="link4_sensor2_rgb_sensor">
      <always_on>true</always_on>
      <update_rate>30.0</update_rate>
      <visualize>false</visualize>
      <camera name="link4_sensor2_rgb_camera">
        <horizontal_fov>2.0943951023932</horizontal_fov>
        <image>
          <width>800</width>
          <height>600</height>
          <format>R8G8B8</format>
        </image>
        <clip>
          <near>0.05</near>
          <far>5.0</far>
        </clip>
      </camera>
      <plugin name="link4_sensor2_rgb_ros_plugin" filename="libgazebo_ros_camera.so">
        <alwaysOn>true</alwaysOn>
        <updateRate>0.0</updateRate>
        <cameraName>link4_sensor2_rgb</cameraName>
        <imageTopicName>/link4_sensor2/rgb/image_raw</imageTopicName>
        <cameraInfoTopicName>/link4_sensor2/rgb/camera_info</cameraInfoTopicName>
        <frameName>link4_sensor2_camera_link</frameName>
        <distortionK1>0.0</distortionK1>
        <distortionK2>0.0</distortionK2>
        <distortionK3>0.0</distortionK3>
        <distortionT1>0.0</distortionT1>
        <distortionT2>0.0</distortionT2>
      </plugin>
    </sensor>
  </gazebo>

  <!-- link4_sensor2 ToF approximation: ideal depth plus PointCloud2 -->
  <gazebo reference="link4_sensor2_tof_gz_link">
    <sensor type="depth" name="link4_sensor2_tof_sensor">
      <always_on>true</always_on>
      <update_rate>30.0</update_rate>
      <visualize>false</visualize>
      <camera name="link4_sensor2_tof_camera">
        <horizontal_fov>0.9599310885968813</horizontal_fov>
        <image>
          <width>320</width>
          <height>240</height>
          <format>R8G8B8</format>
        </image>
        <clip>
          <near>0.15</near>
          <far>0.75</far>
        </clip>
      </camera>
      <plugin name="link4_sensor2_tof_ros_plugin" filename="libgazebo_ros_openni_kinect.so">
        <baseline>0.0</baseline>
        <alwaysOn>true</alwaysOn>
        <updateRate>0.0</updateRate>
        <cameraName>link4_sensor2_tof</cameraName>
        <imageTopicName>/link4_sensor2/tof/internal_rgb_unused/image_raw</imageTopicName>
        <cameraInfoTopicName>/link4_sensor2/tof/internal_rgb_unused/camera_info</cameraInfoTopicName>
        <depthImageTopicName>/link4_sensor2/tof/depth_raw</depthImageTopicName>
        <depthImageCameraInfoTopicName>/link4_sensor2/tof/camera_info</depthImageCameraInfoTopicName>
        <pointCloudTopicName>/link4_sensor2/tof/cloud</pointCloudTopicName>
        <frameName>link4_sensor2_tof_link</frameName>
        <pointCloudCutoff>0.15</pointCloudCutoff>
        <pointCloudCutoffMax>0.75</pointCloudCutoffMax>
      </plugin>
    </sensor>
  </gazebo>


  <!-- ================================================================ -->
  <!-- Gazebo ros_control position-interface transmissions              -->
  <!-- ================================================================ -->

  <!-- ================================================================ -->
  <!-- Kinematic Gazebo rendering mode                                  -->
  <!-- The arm state is supplied by arm_sim_node via                     -->
  <!-- /gazebo/set_model_configuration, not by Gazebo dynamics.          -->
  <!-- Disable gravity so unactuated joints do not sag between syncs.    -->
  <!-- ================================================================ -->
  <gazebo reference="base_link">
    <gravity>false</gravity>
  </gazebo>
  <gazebo reference="link1">
    <gravity>false</gravity>
  </gazebo>
  <gazebo reference="link2">
    <gravity>false</gravity>
  </gazebo>
  <gazebo reference="link2_sensor1_link">
    <gravity>false</gravity>
  </gazebo>
  <gazebo reference="link2_sensor1_camera_link">
    <gravity>false</gravity>
  </gazebo>
  <gazebo reference="link2_sensor1_tof_link">
    <gravity>false</gravity>
  </gazebo>
  <gazebo reference="link2_sensor2_link">
    <gravity>false</gravity>
  </gazebo>
  <gazebo reference="link2_sensor2_camera_link">
    <gravity>false</gravity>
  </gazebo>
  <gazebo reference="link2_sensor2_tof_link">
    <gravity>false</gravity>
  </gazebo>
  <gazebo reference="link3">
    <gravity>false</gravity>
  </gazebo>
  <gazebo reference="link3_sensor1_link">
    <gravity>false</gravity>
  </gazebo>
  <gazebo reference="link3_sensor1_camera_link">
    <gravity>false</gravity>
  </gazebo>
  <gazebo reference="link3_sensor1_tof_link">
    <gravity>false</gravity>
  </gazebo>
  <gazebo reference="link3_sensor2_link">
    <gravity>false</gravity>
  </gazebo>
  <gazebo reference="link3_sensor2_camera_link">
    <gravity>false</gravity>
  </gazebo>
  <gazebo reference="link3_sensor2_tof_link">
    <gravity>false</gravity>
  </gazebo>
  <gazebo reference="link4">
    <gravity>false</gravity>
  </gazebo>
  <gazebo reference="link4_sensor1_link">
    <gravity>false</gravity>
  </gazebo>
  <gazebo reference="link4_sensor1_camera_link">
    <gravity>false</gravity>
  </gazebo>
  <gazebo reference="link4_sensor1_tof_link">
    <gravity>false</gravity>
  </gazebo>
  <gazebo reference="link4_sensor2_link">
    <gravity>false</gravity>
  </gazebo>
  <gazebo reference="link4_sensor2_camera_link">
    <gravity>false</gravity>
  </gazebo>
  <gazebo reference="link4_sensor2_tof_link">
    <gravity>false</gravity>
  </gazebo>
  <gazebo reference="wrist_link1">
    <gravity>false</gravity>
  </gazebo>
  <gazebo reference="wrist_link2">
    <gravity>false</gravity>
  </gazebo>
  <gazebo reference="wrist_link3">
    <gravity>false</gravity>
  </gazebo>
  <gazebo reference="EE_sensor1_link">
    <gravity>false</gravity>
  </gazebo>
  <gazebo reference="EE_sensor1_camera_link">
    <gravity>false</gravity>
  </gazebo>
  <gazebo reference="EE_sensor1_tof_link">
    <gravity>false</gravity>
  </gazebo>
  <gazebo reference="EE_snesor2_link">
    <gravity>false</gravity>
  </gazebo>
  <gazebo reference="EE_sensor2_camera_link">
    <gravity>false</gravity>
  </gazebo>
  <gazebo reference="EE_sensor2_tof_link">
    <gravity>false</gravity>
  </gazebo>
  <gazebo reference="EE_link">
    <gravity>false</gravity>
  </gazebo>
  <gazebo reference="link4_sensor1_camera_gz_link">
    <gravity>false</gravity>
  </gazebo>
  <gazebo reference="link4_sensor1_tof_gz_link">
    <gravity>false</gravity>
  </gazebo>
  <gazebo reference="link4_sensor2_camera_gz_link">
    <gravity>false</gravity>
  </gazebo>
  <gazebo reference="link4_sensor2_tof_gz_link">
    <gravity>false</gravity>
  </gazebo>

</robot>